{
  "meta": [
    {
      "integer": 5,
      "key": "z1"
    },
    {
      "integer": 10,
      "key": "z2"
    }
  ],
  "xsize": 6,
  "zsize": 11,
  "palette": {
    "palette": [
      {
        "char": "i",
        "block": "horror_elements_mod:flashing_lamp_1"
      },
      {
        "char": "f",
        "block": "vm:vending_machine[bottom=false,facing=north]"
      },
      {
        "char": "e",
        "block": "vm:vending_machine[bottom=true,facing=north]"
      }
    ]
  },
  "slices": [
    [
      "      ",
      "      ",
      "      ",
      "      ",
      "ee    ",
      "xxxxxx",
      "xxxxx/",
      "xxxxx/",
      "xxxxx/",
      "xxxxx/",
      "xxxxxx"
    ],
    [
      "      ",
      "      ",
      "      ",
      "      ",
      "ff    ",
      "xxxxx_",
      "xxxx/ ",
      "xxxx/ ",
      "xxxx/ ",
      "xxxx/ ",
      "xxxxx_"
    ],
    [
      "      ",
      "      ",
      "      ",
      "      ",
      "      ",
      "xxix_ ",
      "xxx/  ",
      "xxx/  ",
      "xxx/  ",
      "xxx/  ",
      "xxix_ "
    ],
    [
      "      ",
      "      ",
      "      ",
      "      ",
      "      ",
      "xxx_  ",
      "xx/   ",
      "xx/   ",
      "xx/   ",
      "xx/   ",
      "xxx_  "
    ],
    [
      "      ",
      "      ",
      "      ",
      "      ",
      "      ",
      "xx_   ",
      "x/    ",
      "x/    ",
      "x/    ",
      "x/    ",
      "xx_   "
    ],
    [
      "      ",
      "      ",
      "      ",
      "      ",
      "      ",
      "x_    ",
      "/     ",
      "/     ",
      "/     ",
      "/     ",
      "x_    "
    ],
    [
      "      ",
      "      ",
      "      ",
      "      ",
      "      ",
      "_     ",
      "      ",
      "      ",
      "      ",
      "      ",
      "_     "
    ]
  ]
}